<?xml version="1.0" ?>
<sdf version="1.5">
  <model name="ugv">
		<%=chassis_wid=0.4 %>
		<%=chassis_hgt=0.2 %>
		<%=chassis_len=1.0 %>
    <pose>0.0 0.0 0.0 0 0 0</pose>
		<link name="steerbot_footprint"/>

    <joint name="steerbot_footprint_joint" type="fixed">
			<pose>0.0 0.0 0 0 0 0</pose>
      <parent>steerbot_footprint</parent>
      <child>steerbot_chassis</child>
    </joint> 


    <link name="steerbot_chassis">
        <pose> 0 0 0.4 0 0 0</pose>
        <!--inertial>
            <mass value="${chassis_mas}"/>
            <origin xyz="0 0 0" rpy="0 0 0"/>
            <inertia ixx="${1./12.*(chassis_wid_sq + chassis_hgt_sq)}" 
                     iyy="${1./12.*(chassis_wid_sq + chassis_len_sq)}" 
                     izz="${1./12.*(chassis_hgt_sq + chassis_len_sq)}" 
                     ixy="0.0" ixz="0.0" iyz="0.0" 
                     />
         </inertial-->
				
        <!--collision name="chassis_collision">
            <geometry>
                <box><%=chassis_len%> <%=chassis_wid%> <%=chassis_hgt%></box>
            </geometry>
        </collision>

        <visual name="chassis_visual">
            <geometry>
                <box><%=chassis_len%> <%=chassis_wid%> <%=chassis_hgt%></box>
            </geometry>
        </visual-->
      <collision name="collision_base">
        <geometry>
          <box>
            <size>0.6 0.3 0.1</size>
          </box>
        </geometry>
				<!--surface>
					<friction>
							<ode>
							<mu>0</mu>
							<mu2>0</mu2>
							<slip1>1.0</slip1>
							<slip2>1.0</slip2>
						</ode>
					</friction>
				</surface-->
      </collision>
			<visual name="visual_base">
        <geometry>
          <box>
            <size>0.6 0.3 0.1</size>
          </box>
        </geometry>
        <material>
          <ambient>0.9 0.9 0.9 1</ambient>
          <diffuse>0.3 0.3 0.3 1</diffuse>
          <specular>0.1 0.1 0.1 1</specular>
          <emissive>0.0 0.0 0.0 1</emissive>
        </material>
      </visual>
    </link>

		<link name="base_link">
      <inertial>
        <mass>5.0</mass>
        <inertia>
          <ixx>0.5</ixx>
          <ixy>0</ixy>
          <ixz>0</ixz>
          <iyy>1.0</iyy>
          <iyz>0</iyz>
          <izz>0.1</izz>
        </inertia>
      </inertial>
      <collision name="collision_base">
        <geometry>
          <box>
            <size>0.6 0.3 0.1</size>
          </box>
        </geometry>
				<!--surface>
					<friction>
							<ode>
							<mu>0</mu>
							<mu2>0</mu2>
							<slip1>1.0</slip1>
							<slip2>1.0</slip2>
						</ode>
					</friction>
				</surface-->
      </collision>
			<visual name="visual_base">
        <geometry>
          <box>
            <size>0.6 0.3 0.1</size>
          </box>
        </geometry>
        <material>
          <ambient>0.9 0.9 0.9 1</ambient>
          <diffuse>0.3 0.3 0.3 1</diffuse>
          <specular>0.1 0.1 0.1 1</specular>
          <emissive>0.0 0.0 0.0 1</emissive>
        </material>
      </visual>
		</link>

		<link name="front_right_axis">
      <pose>0.25 -0.15 -0.05 -1.57079 0 0</pose>
		</link>
		<link name="front_left_axis">
      <pose>0.25 0.15 -0.05 -1.57079 0 0</pose>
		</link>

		<link name="front_right_wheel">
      <pose>0.25 -0.15 -0.05 -1.57079 0 0</pose>
      <!--inertial>
        <mass>0.1</mass>
        <inertia>
          <ixx>5.1458-5</ixx>
          <ixy>0</ixy>
          <ixz>0</ixz>
          <iyy>5.1458-5</iyy>
          <iyz>0</iyz>
          <izz>6.125-5</izz>
        </inertia>
      </inertial-->
      <collision name="collision_front_right_wheel">
        <geometry>
          <cylinder>
            <length>0.1</length>
						<radius>0.1</radius>
          </cylinder>
        </geometry>
      </collision>
			<visual name="visual_front_right_wheel">
        <geometry>
          <cylinder>
            <length>0.1</length>
						<radius>0.1</radius>
          </cylinder>
        </geometry>
        <material>
          <ambient>0.4 0.4 0.4 1</ambient>
          <diffuse>0.2 0.2 0.2 1</diffuse>
          <specular>0.1 0.1 0.1 1</specular>
          <emissive>0.0 0.0 0.0 1</emissive>
        </material>
      </visual>
		</link>

		<link name="front_left_wheel">
      <pose>0.25 0.15 -0.05 -1.57079 0 0</pose>
      <!--inertial>
        <mass>0.1</mass>
        <inertia>
          <ixx>5.1458-5</ixx>
          <ixy>0</ixy>
          <ixz>0</ixz>
          <iyy>5.1458-5</iyy>
          <iyz>0</iyz>
          <izz>6.125-5</izz>
        </inertia>
      </inertial-->
      <collision name="collision_front_left_wheel">
        <geometry>
          <cylinder>
            <length>0.1</length>
						<radius>0.1</radius>
          </cylinder>
        </geometry>
      </collision>
			<visual name="visual_front_left_wheel">
        <geometry>
          <cylinder>
            <length>0.1</length>
						<radius>0.1</radius>
          </cylinder>
        </geometry>
        <material>
          <ambient>0.4 0.4 0.4 1</ambient>
          <diffuse>0.2 0.2 0.2 1</diffuse>
          <specular>0.1 0.1 0.1 1</specular>
          <emissive>0.0 0.0 0.0 1</emissive>
        </material>
      </visual>
		</link>


		<link name="rear_right_wheel">
      <pose>-0.2825 -0.17 -0.05 -1.57079 0 0</pose>
      <!--inertial>
        <mass>0.1</mass>
        <inertia>
          <ixx>5.1458-5</ixx>
          <ixy>0</ixy>
          <ixz>0</ixz>
          <iyy>5.1458-5</iyy>
          <iyz>0</iyz>
          <izz>6.125-5</izz>
        </inertia>
      </inertial-->
      <collision name="collision_rear_right_wheel">
        <geometry>
          <cylinder>
            <length>0.1</length>
						<radius>0.1</radius>
          </cylinder>
        </geometry>
      </collision>
			<visual name="visual_rear_right_wheel">
        <geometry>
          <cylinder>
            <length>0.1</length>
						<radius>0.1</radius>
          </cylinder>
        </geometry>
        <material>
          <ambient>0.4 0.4 0.4 1</ambient>
          <diffuse>0.2 0.2 0.2 1</diffuse>
          <specular>0.1 0.1 0.1 1</specular>
          <emissive>0.0 0.0 0.0 1</emissive>
        </material>
      </visual>
		</link>

		<link name="rear_left_wheel">
      <pose>-0.2825 0.17 -0.05 -1.57079 0 0</pose>
      <!--inertial>
        <mass>0.1</mass>
        <inertia>
          <ixx>5.1458-5</ixx>
          <ixy>0</ixy>
          <ixz>0</ixz>
          <iyy>5.1458-5</iyy>
          <iyz>0</iyz>
          <izz>6.125-5</izz>
        </inertia>
      </inertial-->
      <collision name="collision_rear_left_wheel">
        <geometry>
          <cylinder>
            <length>0.1</length>
						<radius>0.1</radius>
          </cylinder>
        </geometry>
      </collision>
			<visual name="visual_rear_left_wheel">
        <geometry>
          <cylinder>
            <length>0.1</length>
						<radius>0.1</radius>
          </cylinder>
        </geometry>
        <material>
          <ambient>0.4 0.4 0.4 1</ambient>
          <diffuse>0.2 0.2 0.2 1</diffuse>
          <specular>0.1 0.1 0.1 1</specular>
          <emissive>0.0 0.0 0.0 1</emissive>
        </material>
      </visual>
		</link>



    <joint name="front_right_axis_joint" type="revolute">
			<!--pose>0.3 0.0 0 0 0 0</pose-->
      <child>front_right_axis</child>
      <parent>base_link</parent>
      <axis>
        <xyz>0 1 0</xyz>
      </axis>
    </joint> 

    <joint name="front_left_axis_joint" type="revolute">
			<!--pose>0.3 0.0 0 0 0 0</pose-->
      <child>front_left_axis</child>
      <parent>base_link</parent>
      <axis>
        <xyz>0 1 0</xyz>
      </axis>
    </joint> 

    <joint name="front_right_wheel_joint" type="revolute">
			<!--pose>0.3 0.0 0 0 0 0</pose-->
      <child>front_right_wheel</child>
      <parent>front_right_axis</parent>
      <axis>
        <xyz>0 0 1</xyz>
      </axis>
    </joint> 

    <joint name="front_left_wheel_joint" type="revolute">
			<!--pose>0.3 0.0 0 0 0 0</pose-->
      <child>front_left_wheel</child>
      <parent>front_left_axis</parent>
      <axis>
        <xyz>0 0 1</xyz>
      </axis>
    </joint> 


    <joint name="rear_right_wheel_joint" type="revolute">
			<!--pose>0.3 0.0 0 0 0 0</pose-->
      <child>rear_right_wheel</child>
      <parent>base_link</parent>
      <axis>
        <xyz>0 0 1</xyz>
      </axis>
    </joint> 

    <joint name="rear_left_wheel_joint" type="revolute">
			<!--pose>0.3 0.0 0 0 0 0</pose-->
      <child>rear_left_wheel</child>
      <parent>base_link</parent>
      <axis>
        <xyz>0 0 1</xyz>
      </axis>
    </joint> 



  </model>
</sdf>
